Workbook
Name Slicer_Coles_Forecast: #N/A
Name Slicer_State: #N/A
Name Slicer_Targeted_Quarter: #N/A

Sheet ColesSalesData
B1: Coles_StoreIDNo | C1: Expec_Revenue | D1: Gross_Sale | E1: Sales_Cost | F1: Targeted_Quarter | G1: Coles_Forecast
A2: 1 | B2: C524 | C2: 39 | D2: 56 | E2: 6 | F2: Q2 2023 | G2: On Target
A3: 2 | B3: C624 | C3: 22 | D3: 55 | E3: 7 | F3: Q1 2023 | G3: On Target
A4: 3 | B4: C460 | C4: 36 | D4: 51 | E4: 7 | F4: Q1 2023 | G4: On Target
A5: 4 | B5: C708 | C5: 48 | D5: 50 | E5: 10 | F5: Q1 2023 | G5: Below Target
A6: 5 | B6: C647 | C6: 23 | D6: 39 | E6: 18 | F6: Q2 2023 | G6: Below Target
A7: 6 | B7: C713 | C7: 38 | D7: 84 | E7: 15 | F7: Q2 2023 | G7: On Target
A8: 7 | B8: C308 | C8: 31 | D8: 55 | E8: 10 | F8: Q1 2023 | G8: On Target
A9: 8 | B9: C494 | C9: 38 | D9: 44 | E9: 8 | F9: Q1 2023 | G9: Below Target
A10: 9 | B10: C656 | C10: 30 | D10: 39 | E10: 10 | F10: Q2 2023 | G10: Below Target
A11: 10 | B11: C280 | C11: 44 | D11: 26 | E11: 15 | F11: Q1 2023 | G11: Below Target
A12: 11 | B12: C738 | C12: 34 | D12: 29 | E12: 13 | F12: Q1 2023 | G12: Below Target
A13: 12 | B13: C164 | C13: 49 | D13: 45 | E13: 9 | F13: Q2 2023 | G13: Below Target
... A31: 30 | B31: C419 | C31: 25 | D31: 42 | E31: 13 | F31: Q2 2023 | G31: On Target
A32: 31 | B32: C443 | C32: 37 | D32: 57 | E32: NA | F32: Q1 2023 | G32: NA
A33: 32 | B33: C640 | C33: 42 | D33: 55 | E33: 5 | F33: Q1 2023 | G33: On Target
A34: 33 | B34: C317 | C34: 43 | D34: 31 | E34: 8 | F34: Q2 2023 | G34: Below Target
A35: 34 | B35: C207 | C35: 23 | D35: 36 | E35: 11 | F35: Q2 2023 | G35: On Target
A36: 35 | B36: C336 | C36: 41 | D36: 47 | E36: 7 | F36: Q2 2023 | G36: Below Target
A37: 36 | B37: C309 | C37: 40 | D37: 29 | E37: 5 | F37: Q2 2023 | G37: Below Target
A38: 37 | B38: C163 | C38: 30 | D38: 59 | E38: 9 | F38: Q2 2023 | G38: On Target
A39: 38 | B39: C461 | C39: 29 | D39: 50 | E39: 20 | F39: Q1 2023 | G39: On Target
A40: 39 | B40: C628 | C40: 34 | D40: 38 | E40: 6 | F40: Q1 2023 | G40: Below Target
A41: 40 | B41: C759 | C41: 38 | D41: 32 | E41: 10 | F41: Q1 2023 | G41: Below Target
A42: 41 | B42: C463 | C42: 24 | D42: 30 | E42: 10 | F42: Q1 2023 | G42: Below Target
A43: 42 | B43: C203 | C43: 48 | D43: 55 | E43: 7 | F43: Q1 2023 | G43: On Target
A44: 43 | B44: C245 | C44: 28 | D44: 50 | E44: 7 | F44: Q1 2023 | G44: On Target
... A55: 54 | B55: C493 | C55: 44 | D55: 54 | E55: 10 | F55: Q1 2023 | G55: On Target
A56: 55 | B56: C583 | C56: 43 | D56: 29 | E56: NA | F56: Q2 2023 | G56: NA
A57: 56 | B57: C794 | C57: 34 | D57: 35 | E57: 5 | F57: Q1 2023 | G57: Below Target
A58: 57 | B58: C431 | C58: 45 | D58: 42 | E58: 9 | F58: Q2 2023 | G58: Below Target
A59: 58 | B59: C348 | C59: 27 | D59: 40 | E59: 13 | F59: Q1 2023 | G59: On Target
A60: 59 | B60: C694 | C60: 28 | D60: 39 | E60: 9 | F60: Q1 2023 | G60: On Target
A61: 60 | B61: C218 | C61: 24 | D61: 43 | E61: 9 | F61: Q1 2023 | G61: On Target
A62: 61 | B62: C349 | C62: 29 | D62: 43 | E62: 12 | F62: Q2 2023 | G62: On Target
A63: 62 | B63: C674 | C63: 36 | D63: 47 | E63: 10 | F63: Q2 2023 | G63: On Target
A64: 63 | B64: C773 | C64: 48 | D64: 50 | E64: 6 | F64: Q2 2023 | G64: Below Target
A65: 64 | B65: C182 | C65: 42 | D65: 56 | E65: 13 | F65: Q1 2023 | G65: On Target
A66: 65 | B66: C664 | C66: 41 | D66: 41 | E66: 11 | F66: Q2 2023 | G66: Below Target
A67: 66 | B67: C192 | C67: 50 | D67: 36 | E67: 11 | F67: Q2 2023 | G67: Below Target
...

Sheet ColesStoreData
B1: Coles_StoreID | C1: Store_Location | D1: Customer_Count | E1: Staff_Count | F1: Store_Area
A2: 1 | B2: C524 | C2: QLD | D2: 18445 | E2: 36 | F2: 2500
A3: 2 | B3: C624 | C3: NSW | D3: 40535 | E3: 37 | F3: 2500
A4: 3 | B4: C460 | C4: VIC | D4: 6146 | E4: 19 | F4: 1900
A5: 4 | B5: C708 | C5: SA | D5: 9151 | E5: 23 | F5: 1900
A6: 5 | B6: C647 | C6: NSW | D6: 9308 | E6: 23 | F6: 1700
A7: 6 | B7: C713 | C7: QLD | D7: 58430 | E7: 27 | F7: 2500
A8: 7 | B8: C308 | C8: VIC | D8: 38603 | E8: 31 | F8: 2500
A9: 8 | B9: C494 | C9: QLD | D9: 9545 | E9: 19 | F9: 1700
A10: 9 | B10: C656 | C10: VIC | D10: 9357 | E10: 17 | F10: 1700
A11: 10 | B11: C280 | C11: WA | D11: 8389 | E11: 22 | F11: 1700
A12: 11 | B12: C738 | C12: VIC | D12: 8953 | E12: 18 | F12: 1700
A13: 12 | B13: C164 | C13: ACT | D13: 7927 | E13: 20 | F13: 1900
... A23: 22 | B23: C672 | C23: SA | D23: 9850 | E23: 26 | F23: 1700
A24: 23 | B24: C313 | C24: NSW | D24: NA | E24: 39 | F24: 2500
A25: 24 | B25: C450 | C25: NSW | D25: 7566 | E25: 16 | F25: 1900
A26: 25 | B26: C699 | C26: VIC | D26: 7221 | E26: 26 | F26: 1900
A27: 26 | B27: C760 | C27: NSW | D27: 9149 | E27: 19 | F27: 1700
A28: 27 | B28: C174 | C28: NSW | D28: 7358 | E28: 20 | F28: 1700
A29: 28 | B29: C344 | C29: VIC | D29: 9657 | E29: 23 | F29: 1700
A30: 29 | B30: C382 | C30: NSW | D30: 7431 | E30: 18 | F30: 1900
A31: 30 | B31: C419 | C31: NSW | D31: 7250 | E31: 15 | F31: 1700
A32: 31 | B32: C443 | C32: QLD | D32: 8035 | E32: 32 | F32: 2500
A33: 32 | B33: C640 | C33: QLD | D33: 50859 | E33: 25 | F33: 2500
A34: 33 | B34: C317 | C34: QLD | D34: 9122 | E34: 26 | F34: 1700
A35: 34 | B35: C207 | C35: NSW | D35: NA | E35: 15 | F35: 1700
A36: 35 | B36: C336 | C36: QLD | D36: 9741 | E36: 25 | F36: 1900
A37: 36 | B37: C309 | C37: QLD | D37: 6948 | E37: 25 | F37: 1700
A38: 37 | B38: C163 | C38: VIC | D38: 25397 | E38: 33 | F38: 2700
A39: 38 | B39: C461 | C39: VIC | D39: 9534 | E39: 16 | F39: 1900
A40: 39 | B40: C628 | C40: VIC | D40: 9912 | E40: 24 | F40: 1700
A41: 40 | B41: C759 | C41: QLD | D41: 7869 | E41: 16 | F41: 1700
A42: 41 | B42: C463 | C42: NSW | D42: 9097 | E42: 19 | F42: 1700
A43: 42 | B43: C203 | C43: SA | D43: 22370 | E43: 30 | F43: 2500
A44: 43 | B44: C245 | C44: NSW | D44: 8363 | E44: 20 | F44: 1900
A45: 44 | B45: C562 | C45: VIC | D45: 9242 | E45: 25 | F45: 1700
A46: 45 | B46: C442 | C46: ACT | D46: 9026 | E46: 19 | F46: 1700
A47: 46 | B47: C776 | C47: NSW | D47: 9015 | E47: 26 | F47: 1700
... A60: 59 | B60: C694 | C60: NSW | D60: 6624 | E60: 23 | F60: 1700
A61: 60 | B61: C218 | C61: NSW | D61: NA | E61: 25 | F61: 1700
...

Sheet Working Sheet
B1: Coles_StoreIDNo | C1: Expec_Revenue | D1: Gross_Sale | E1: Sales_Cost | F1: Targeted_Quarter | G1: Coles_Forecast | H1: State | I1: Customer_Count | J1: Store_data | K1: Profit | L1: Profit_Margin
A2: 1 | B2: C524 | C2: 39 | D2: 56 | E2: 6 | F2: Q2 2023 | G2: On Target | H2: =VLOOKUP(B2,ColesStoreData!$B:$F,2,0) -> QLD | I2: =VLOOKUP(B2,ColesStoreData!$B:$F,3,0) -> 18445 | J2: =VLOOKUP(B2,ColesStoreData!$B:$F,5,0) -> 2500 | K2: =D2-E2 -> 50 | L2: =K2/D2 -> 0.89285714
A3: 2 | B3: C624 | C3: 22 | D3: 55 | E3: 7 | F3: Q1 2023 | G3: On Target | H3: =VLOOKUP(B3,ColesStoreData!$B:$F,2,0) -> NSW | I3: =VLOOKUP(B3,ColesStoreData!$B:$F,3,0) -> 40535 | J3: =VLOOKUP(B3,ColesStoreData!$B:$F,5,0) -> 2500 | K3: =D3-E3 -> 48 | L3: =K3/D3 -> 0.87272727
A4: 3 | B4: C460 | C4: 36 | D4: 51 | E4: 7 | F4: Q1 2023 | G4: On Target | H4: =VLOOKUP(B4,ColesStoreData!$B:$F,2,0) -> VIC | I4: =VLOOKUP(B4,ColesStoreData!$B:$F,3,0) -> 6146 | J4: =VLOOKUP(B4,ColesStoreData!$B:$F,5,0) -> 1900 | K4: =D4-E4 -> 44 | L4: =K4/D4 -> 0.8627451
A5: 4 | B5: C708 | C5: 48 | D5: 50 | E5: 10 | F5: Q1 2023 | G5: Below Target | H5: =VLOOKUP(B5,ColesStoreData!$B:$F,2,0) -> SA | I5: =VLOOKUP(B5,ColesStoreData!$B:$F,3,0) -> 9151 | J5: =VLOOKUP(B5,ColesStoreData!$B:$F,5,0) -> 1900 | K5: =D5-E5 -> 40 | L5: =K5/D5 -> 0.8
A6: 5 | B6: C647 | C6: 23 | D6: 39 | E6: 18 | F6: Q2 2023 | G6: Below Target | H6: =VLOOKUP(B6,ColesStoreData!$B:$F,2,0) -> NSW | I6: =VLOOKUP(B6,ColesStoreData!$B:$F,3,0) -> 9308 | J6: =VLOOKUP(B6,ColesStoreData!$B:$F,5,0) -> 1700 | K6: =D6-E6 -> 21 | L6: =K6/D6 -> 0.53846154
A7: 6 | B7: C713 | C7: 38 | D7: 84 | E7: 15 | F7: Q2 2023 | G7: On Target | H7: =VLOOKUP(B7,ColesStoreData!$B:$F,2,0) -> QLD | I7: =VLOOKUP(B7,ColesStoreData!$B:$F,3,0) -> 58430 | J7: =VLOOKUP(B7,ColesStoreData!$B:$F,5,0) -> 2500 | K7: =D7-E7 -> 69 | L7: =K7/D7 -> 0.82142857
A8: 7 | B8: C308 | C8: 31 | D8: 55 | E8: 10 | F8: Q1 2023 | G8: On Target | H8: =VLOOKUP(B8,ColesStoreData!$B:$F,2,0) -> VIC | I8: =VLOOKUP(B8,ColesStoreData!$B:$F,3,0) -> 38603 | J8: =VLOOKUP(B8,ColesStoreData!$B:$F,5,0) -> 2500 | K8: =D8-E8 -> 45 | L8: =K8/D8 -> 0.81818182
A9: 8 | B9: C494 | C9: 38 | D9: 44 | E9: 8 | F9: Q1 2023 | G9: Below Target | H9: =VLOOKUP(B9,ColesStoreData!$B:$F,2,0) -> QLD | I9: =VLOOKUP(B9,ColesStoreData!$B:$F,3,0) -> 9545 | J9: =VLOOKUP(B9,ColesStoreData!$B:$F,5,0) -> 1700 | K9: =D9-E9 -> 36 | L9: =K9/D9 -> 0.81818182
A10: 9 | B10: C656 | C10: 30 | D10: 39 | E10: 10 | F10: Q2 2023 | G10: Below Target | H10: =VLOOKUP(B10,ColesStoreData!$B:$F,2,0) -> VIC | I10: =VLOOKUP(B10,ColesStoreData!$B:$F,3,0) -> 9357 | J10: =VLOOKUP(B10,ColesStoreData!$B:$F,5,0) -> 1700 | K10: =D10-E10 -> 29 | L10: =K10/D10 -> 0.74358974
A11: 10 | B11: C280 | C11: 44 | D11: 26 | E11: 15 | F11: Q1 2023 | G11: Below Target | H11: =VLOOKUP(B11,ColesStoreData!$B:$F,2,0) -> WA | I11: =VLOOKUP(B11,ColesStoreData!$B:$F,3,0) -> 8389 | J11: =VLOOKUP(B11,ColesStoreData!$B:$F,5,0) -> 1700 | K11: =D11-E11 -> 11 | L11: =K11/D11 -> 0.42307692
A12: 11 | B12: C738 | C12: 34 | D12: 29 | E12: 13 | F12: Q1 2023 | G12: Below Target | H12: =VLOOKUP(B12,ColesStoreData!$B:$F,2,0) -> VIC | I12: =VLOOKUP(B12,ColesStoreData!$B:$F,3,0) -> 8953 | J12: =VLOOKUP(B12,ColesStoreData!$B:$F,5,0) -> 1700 | K12: =D12-E12 -> 16 | L12: =K12/D12 -> 0.55172414
A13: 12 | B13: C164 | C13: 49 | D13: 45 | E13: 9 | F13: Q2 2023 | G13: Below Target | H13: =VLOOKUP(B13,ColesStoreData!$B:$F,2,0) -> ACT | I13: =VLOOKUP(B13,ColesStoreData!$B:$F,3,0) -> 7927 | J13: =VLOOKUP(B13,ColesStoreData!$B:$F,5,0) -> 1900 | K13: =D13-E13 -> 36 | L13: =K13/D13 -> 0.8
... A612: 682 | B612: C249 | C612: 36 | D612: 40 | E612: 8 | F612: Q2 2023 | G612: Below Target | H612: =VLOOKUP(B612,ColesStoreData!$B:$F,2,0) -> VIC | I612: =VLOOKUP(B612,ColesStoreData!$B:$F,3,0) -> 7063 | J612: =VLOOKUP(B612,ColesStoreData!$B:$F,5,0) -> 1700 | K612: =D612-E612 -> 32 | L612: =K612/D612 -> 0.8

Sheet Pivot Table
A3: Row Labels | B3: Sum of Profit | C3: Sum of Gross_Sale
A4: ACT | B4: 102 | C4: 115
A5: NSW | B5: 4715 | C5: 5972
A6: QLD | B6: 1980 | C6: 2363
A7: SA | B7: 96 | C7: 114
A8: TAS | B8: 71 | C8: 78
A9: VIC | B9: 3448 | C9: 4315
A10: WA | B10: 674 | C10: 793
A11: Grand Total | B11: 11086 | C11: 13750
A28: Row Labels | B28: Sum of Gross_Sale | C28: Count of Coles_StoreIDNo
A29: On Target | B29: 13750 | C29: 277
A30: Grand Total | B30: 13750 | C30: 277
A49: Sum of Gross_Sale | B49: Column Labels
A50: Row Labels | B50: Below Target | C50: On Target | D50: Grand Total
A51: Q1 2023 | B51: 6043 | C51: 7091 | D51: 13134
A52: Q2 2023 | B52: 6291 | C52: 6659 | D52: 12950
A53: Grand Total | B53: 12334 | C53: 13750 | D53: 26084

Sheet Dashboard
A1: Coles Supermarket Sales Dashboard — Australia 2023
